<?xml version="1.0" encoding="UTF-8"?>
<!-- Generated by org.testng.reporters.JUnitXMLReporter -->
<testsuite ignored="0" hostname="Guru" failures="2" tests="4" name="Test" time="29.78" errors="0" timestamp="2023-11-17T14:44:02 IST">
  <testcase classname="com.main.base.Test_Cases" name="login" time="7.168"/>
  <testcase classname="com.main.base.Test_Cases" name="loginTest" time="12.551"/>
  <testcase classname="com.main.base.Test_Cases" name="loginTest" time="4.28">
    <failure type="java.lang.AssertionError" message="expected [https://practicetestautomation.com/logged-in-successfully/] but found [https://practicetestautomation.com/practice-test-login/]">
      <![CDATA[java.lang.AssertionError: expected [https://practicetestautomation.com/logged-in-successfully/] but found [https://practicetestautomation.com/practice-test-login/]
at com.main.base.Test_Cases.loginTest(Test_Cases.java:32)
at java.base/java.util.ArrayList.forEach(ArrayList.java:1511)
... Removed 31 stack frames]]>
    </failure>
  </testcase> <!-- loginTest -->
  <testcase classname="com.main.base.Test_Cases" name="loginTest" time="4.659">
    <failure type="java.lang.AssertionError" message="expected [https://practicetestautomation.com/logged-in-successfully/] but found [https://practicetestautomation.com/practice-test-login/]">
      <![CDATA[java.lang.AssertionError: expected [https://practicetestautomation.com/logged-in-successfully/] but found [https://practicetestautomation.com/practice-test-login/]
at com.main.base.Test_Cases.loginTest(Test_Cases.java:32)
at java.base/java.util.ArrayList.forEach(ArrayList.java:1511)
... Removed 31 stack frames]]>
    </failure>
  </testcase> <!-- loginTest -->
</testsuite> <!-- Test -->
